<robot name="unnamed" version="1.0">
  <joint name="l_door_link_joint" type="revolute">
    <limit lower="-1.57000" upper="1.57000" effort="0.00000" velocity="0.00000"/>
    <origin rpy="0.00000 0.00000 0.00000" xyz="1.49683 -2.46089 0.55928"/>
    <parent link="TEMP_link"/>
    <child link="l_door_link"/>
    <axis xyz="0.00000 0.00000 1.00000"/>
  </joint>
  <joint name="r_door_link_joint" type="revolute">
    <limit lower="-1.57000" upper="1.57000" effort="0.00000" velocity="0.00000"/>
    <origin rpy="0.00000 0.00000 0.00000" xyz="1.49683 -0.91107 0.55928"/>
    <parent link="TEMP_link"/>
    <child link="r_door_link"/>
    <axis xyz="0.00000 0.00000 1.00000"/>
  </joint>
  <link name="TEMP_link">
  </link>
  <link name="l_door_link">
    <collision name="l_door_collision">
      <origin rpy="0.00000 0.00000 0.00000" xyz="0.00000 0.39887 0.00000"/>
      <geometry>
        <box size="0.06000 0.73700 1.34866"/>
      </geometry>
    </collision>
    <visual name="l_door">
      <material name="None"/>
      <origin rpy="0.00000 0.00000 0.00000" xyz="0.00000 0.39887 0.00000"/>
      <geometry>
        <box size="0.06000 0.73700 1.34866"/>
      </geometry>
    </visual>
  </link>
  <link name="r_door_link">
    <collision name="r_door_collision">
      <origin rpy="0.00000 0.00000 0.00000" xyz="0.00000 -0.37000 0.00000"/>
      <geometry>
        <box size="0.06000 0.73700 1.34866"/>
      </geometry>
    </collision>
    <visual name="r_door">
      <material name="None"/>
      <origin rpy="0.00000 0.00000 0.00000" xyz="0.00000 -0.37000 0.00000"/>
      <geometry>
        <box size="0.06000 0.73700 1.34866"/>
      </geometry>
    </visual>
  </link>
</robot>