<robot name="unnamed" version="1.0">
  <joint name="Wheel_Front_Left_link_joint" type="continuous">
    <limit effort="20.00000" velocity="20.00000"/>
    <origin rpy="1.57080 0.00000 -3.14159" xyz="1.99946 1.36357 -0.17449"/>
    <parent link="root"/>
    <child link="Wheel_Front_Left_link"/>
    <axis xyz="0.00000 0.00000 1.00000"/>
  </joint>
  <joint name="Wheel_Front_Right_link_joint" type="continuous">
    <limit effort="20.00000" velocity="20.00000"/>
    <origin rpy="-1.57080 0.00000 0.00000" xyz="1.99946 -1.36357 -0.17449"/>
    <parent link="root"/>
    <child link="Wheel_Front_Right_link"/>
    <axis xyz="0.00000 0.00000 1.00000"/>
  </joint>
  <joint name="Wheel_Rear_Left_link_joint" type="continuous">
    <limit effort="20.00000" velocity="20.00000"/>
    <origin rpy="1.57080 0.00000 -3.14159" xyz="-1.99946 1.35794 -0.17449"/>
    <parent link="root"/>
    <child link="Wheel_Rear_Left_link"/>
    <axis xyz="0.00000 0.00000 1.00000"/>
  </joint>
  <joint name="Wheel_Rear_Right_link_joint" type="continuous">
    <limit effort="20.00000" velocity="20.00000"/>
    <origin rpy="-1.57080 0.00000 0.00000" xyz="-1.99946 -1.35794 -0.17449"/>
    <parent link="root"/>
    <child link="Wheel_Rear_Right_link"/>
    <axis xyz="0.00000 0.00000 1.00000"/>
  </joint>
  <link name="root">
    <collision name="物体.001_collision">
      <origin rpy="0.00000 0.00000 0.00000" xyz="-1.65184 1.04281 0.71102"/>
      <geometry>
        <mesh filename="../meshes/obj/Plane.003.obj" scale="1.59538 1.59538 1.59538"/>
      </geometry>
    </collision>
    <collision name="物体.002_collision">
      <origin rpy="0.00000 0.00000 0.00000" xyz="1.74062 1.04281 0.71102"/>
      <geometry>
        <mesh filename="../meshes/obj/Plane.004.obj" scale="1.59538 1.59538 1.59538"/>
      </geometry>
    </collision>
    <collision name="物体.003_collision">
      <origin rpy="0.00000 0.00000 0.00000" xyz="-1.52488 -1.07185 0.71102"/>
      <geometry>
        <mesh filename="../meshes/obj/Plane.005.obj" scale="1.59538 1.59538 1.59538"/>
      </geometry>
    </collision>
    <collision name="物体.004_collision">
      <origin rpy="0.00000 0.00000 0.00000" xyz="0.00000 -0.00000 0.00000"/>
      <geometry>
        <mesh filename="../meshes/obj/平面.001.obj" scale="2.79197 1.52711 1.59538"/>
      </geometry>
    </collision>
    <collision name="物体_collision">
      <origin rpy="0.00000 0.00000 0.00000" xyz="2.07142 -0.85163 1.10491"/>
      <geometry>
        <mesh filename="../meshes/obj/Plane.002.obj" scale="1.59538 1.59538 1.59538"/>
      </geometry>
    </collision>
    <collision name="球体.002_collision">
      <origin rpy="0.00000 0.00000 0.00000" xyz="0.00000 0.00000 -0.70738"/>
      <geometry>
        <mesh filename="../meshes/obj/球体.001.obj" scale="1.59538 1.59538 1.59538"/>
      </geometry>
    </collision>
    <collision name="立方体.001_collision">
      <origin rpy="0.00000 0.00000 0.00000" xyz="0.11222 -0.06016 0.74909"/>
      <geometry>
        <mesh filename="../meshes/obj/立方体.003.obj" scale="1.59538 1.59538 1.59538"/>
      </geometry>
    </collision>
    <collision name="立方体.007_collision">
      <origin rpy="0.00000 0.00000 0.00000" xyz="-2.69721 -0.21562 0.83229"/>
      <geometry>
        <mesh filename="../meshes/obj/立方体.001.obj" scale="-0.27436 -1.53690 -0.61519"/>
      </geometry>
    </collision>
    <collision name="立方体.012_collision">
      <origin rpy="0.00000 0.00000 0.00000" xyz="2.78509 0.00003 0.71363"/>
      <geometry>
        <mesh filename="../meshes/obj/立方体.002.obj" scale="-0.27436 -1.53690 -0.61519"/>
      </geometry>
    </collision>
    <visual name="物体">
      <material name="材质.004"/>
      <origin rpy="0.00000 0.00000 0.00000" xyz="2.07142 -0.85163 1.10491"/>
      <geometry>
        <mesh filename="../meshes/obj/Plane.002.obj" scale="1.59538 1.59538 1.59538"/>
      </geometry>
    </visual>
    <visual name="物体.001">
      <material name="材质.004"/>
      <origin rpy="0.00000 0.00000 0.00000" xyz="-1.65184 1.04281 0.71102"/>
      <geometry>
        <mesh filename="../meshes/obj/Plane.003.obj" scale="1.59538 1.59538 1.59538"/>
      </geometry>
    </visual>
    <visual name="物体.002">
      <material name="材质.004"/>
      <origin rpy="0.00000 0.00000 0.00000" xyz="1.74062 1.04281 0.71102"/>
      <geometry>
        <mesh filename="../meshes/obj/Plane.004.obj" scale="1.59538 1.59538 1.59538"/>
      </geometry>
    </visual>
    <visual name="物体.003">
      <material name="材质.004"/>
      <origin rpy="0.00000 0.00000 0.00000" xyz="-1.52488 -1.07185 0.71102"/>
      <geometry>
        <mesh filename="../meshes/obj/Plane.005.obj" scale="1.59538 1.59538 1.59538"/>
      </geometry>
    </visual>
    <visual name="物体.004">
      <material name="材质.004"/>
      <origin rpy="0.00000 0.00000 0.00000" xyz="0.00000 -0.00000 0.00000"/>
      <geometry>
        <mesh filename="../meshes/obj/平面.001.obj" scale="2.79197 1.52711 1.59538"/>
      </geometry>
    </visual>
    <visual name="球体.002">
      <material name="材质.015"/>
      <origin rpy="0.00000 0.00000 0.00000" xyz="0.00000 0.00000 -0.70738"/>
      <geometry>
        <mesh filename="../meshes/obj/球体.001.obj" scale="1.59538 1.59538 1.59538"/>
      </geometry>
    </visual>
    <visual name="立方体.001">
      <material name="材质.004"/>
      <origin rpy="0.00000 0.00000 0.00000" xyz="0.11222 -0.06016 0.74909"/>
      <geometry>
        <mesh filename="../meshes/obj/立方体.003.obj" scale="1.59538 1.59538 1.59538"/>
      </geometry>
    </visual>
    <visual name="立方体.007">
      <material name="材质.004"/>
      <origin rpy="0.00000 0.00000 0.00000" xyz="-2.69721 -0.21562 0.83229"/>
      <geometry>
        <mesh filename="../meshes/obj/立方体.001.obj" scale="-0.27436 -1.53690 -0.61519"/>
      </geometry>
    </visual>
    <visual name="立方体.012">
      <material name="材质.004"/>
      <origin rpy="0.00000 0.00000 0.00000" xyz="2.78509 0.00003 0.71363"/>
      <geometry>
        <mesh filename="../meshes/obj/立方体.002.obj" scale="-0.27436 -1.53690 -0.61519"/>
      </geometry>
    </visual>
  </link>
  <link name="Wheel_Front_Left_link">
    <collision name="Wheel_Front_Left_collision">
      <origin rpy="3.14159 0.00000 -3.14159" xyz="-0.00001 -0.00027 0.00099"/>
      <geometry>
        <cylinder radius="0.52801" length="0.35143"/>
      </geometry>
    </collision>
    <visual name="Wheel_Front_Left">
      <material name="Metal-gray.001"/>
      <origin rpy="1.57080 0.00000 -3.14159" xyz="0.00000 -0.00000 -0.00000"/>
      <geometry>
        <mesh filename="../meshes/obj/Plane.014.obj" scale="1.59538 1.59538 1.59538"/>
      </geometry>
    </visual>
  </link>
  <link name="Wheel_Front_Right_link">
    <collision name="Wheel_Front_Right_collision">
      <origin rpy="3.14159 0.00000 0.00000" xyz="0.00001 0.00027 -0.00099"/>
      <geometry>
        <cylinder radius="0.52800" length="0.35143"/>
      </geometry>
    </collision>
    <visual name="Wheel_Front_Right">
      <material name="Metal-gray.001"/>
      <origin rpy="1.57080 0.00000 0.00000" xyz="0.00000 -0.00000 -0.00000"/>
      <geometry>
        <mesh filename="../meshes/obj/Plane.013.obj" scale="1.59538 1.59538 1.59538"/>
      </geometry>
    </visual>
  </link>
  <link name="Wheel_Rear_Left_link">
    <collision name="Wheel_Rear_Left_collision">
      <origin rpy="3.14159 0.00000 -3.14159" xyz="0.00001 -0.00027 0.00100"/>
      <geometry>
        <cylinder radius="0.52800" length="0.35143"/>
      </geometry>
    </collision>
    <visual name="Wheel_Rear_Left">
      <material name="Metal-gray.001"/>
      <origin rpy="1.57080 0.00000 -3.14159" xyz="-0.00000 -0.00000 -0.00000"/>
      <geometry>
        <mesh filename="../meshes/obj/Plane.016.obj" scale="1.59538 1.59538 1.59538"/>
      </geometry>
    </visual>
  </link>
  <link name="Wheel_Rear_Right_link">
    <collision name="Wheel_Rear_Right_collision">
      <origin rpy="3.14159 0.00000 0.00000" xyz="-0.00001 0.00027 -0.00101"/>
      <geometry>
        <cylinder radius="0.52800" length="0.35143"/>
      </geometry>
    </collision>
    <visual name="Wheel_Rear_Right">
      <material name="Metal-gray.001"/>
      <origin rpy="1.57080 0.00000 0.00000" xyz="-0.00000 -0.00000 -0.00000"/>
      <geometry>
        <mesh filename="../meshes/obj/Plane.012.obj" scale="1.59538 1.59538 1.59538"/>
      </geometry>
    </visual>
  </link>
  <material name="Metal-gray.001">
    <color rgba="0.64706 0.61176 0.54510 1.00000"/>
  </material>
  <material name="材质.004">
    <color rgba="0.00000 0.00000 0.00000 1.00000"/>
  </material>
  <material name="材质.015">
    <color rgba="0.80000 0.80000 0.80000 1.00000"/>
  </material>
</robot>